<?xml version="1.0" encoding="UTF-8"?>
<testng-results skipped="0" failed="1" ignored="0" total="1" passed="0">
  <reporter-output>
  </reporter-output>
  <suite name="Default suite" duration-ms="115" started-at="2017-12-16T19:25:45Z" finished-at="2017-12-16T19:25:45Z">
    <groups>
    </groups>
    <test name="Default test" duration-ms="115" started-at="2017-12-16T19:25:45Z" finished-at="2017-12-16T19:25:45Z">
      <class name="com.epam.moscow.module4.test.CalculatorTestCos">
        <test-method status="PASS" signature="setUp()[pri:0, instance:com.epam.moscow.module4.test.CalculatorTestCos@7c16905e]" name="setUp" is-config="true" duration-ms="29" started-at="2017-12-16T22:25:45Z" finished-at="2017-12-16T22:25:45Z">
          <reporter-output>
          </reporter-output>
        </test-method> <!-- setUp -->
        <test-method status="FAIL" signature="testCos()[pri:0, instance:com.epam.moscow.module4.test.CalculatorTestCos@7c16905e]" name="testCos" duration-ms="21" started-at="2017-12-16T22:25:45Z" finished-at="2017-12-16T22:25:45Z">
          <exception class="java.lang.AssertionError">
            <message>
              <![CDATA[expected [0.5] but found [-0.9524129804151563]]]>
            </message>
            <full-stacktrace>
              <![CDATA[java.lang.AssertionError: expected [0.5] but found [-0.9524129804151563]at org.testng.Assert.fail(Assert.java:96)at org.testng.Assert.failNotEquals(Assert.java:776)at org.testng.Assert.assertEqualsImpl(Assert.java:137)at org.testng.Assert.assertEquals(Assert.java:118)at org.testng.Assert.assertEquals(Assert.java:442)at com.epam.moscow.module4.test.CalculatorTestCos.testCos(CalculatorTestCos.java:11)at sun.reflect.NativeMethodAccessorImpl.invoke0(Native Method)at sun.reflect.NativeMethodAccessorImpl.invoke(NativeMethodAccessorImpl.java:62)at sun.reflect.DelegatingMethodAccessorImpl.invoke(DelegatingMethodAccessorImpl.java:43)at java.lang.reflect.Method.invoke(Method.java:498)at org.testng.internal.MethodInvocationHelper.invokeMethod(MethodInvocationHelper.java:124)at org.testng.internal.Invoker.invokeMethod(Invoker.java:571)at org.testng.internal.Invoker.invokeTestMethod(Invoker.java:707)at org.testng.internal.Invoker.invokeTestMethods(Invoker.java:979)at org.testng.internal.TestMethodWorker.invokeTestMethods(TestMethodWorker.java:125)at org.testng.internal.TestMethodWorker.run(TestMethodWorker.java:109)at org.testng.TestRunner.privateRun(TestRunner.java:648)at org.testng.TestRunner.run(TestRunner.java:505)at org.testng.SuiteRunner.runTest(SuiteRunner.java:455)at org.testng.SuiteRunner.runSequentially(SuiteRunner.java:450)at org.testng.SuiteRunner.privateRun(SuiteRunner.java:415)at org.testng.SuiteRunner.run(SuiteRunner.java:364)at org.testng.SuiteRunnerWorker.runSuite(SuiteRunnerWorker.java:52)at org.testng.SuiteRunnerWorker.run(SuiteRunnerWorker.java:84)at org.testng.TestNG.runSuitesSequentially(TestNG.java:1187)at org.testng.TestNG.runSuitesLocally(TestNG.java:1116)at org.testng.TestNG.runSuites(TestNG.java:1028)at org.testng.TestNG.run(TestNG.java:996)at org.testng.remote.AbstractRemoteTestNG.run(AbstractRemoteTestNG.java:114)at org.testng.remote.RemoteTestNG.initAndRun(RemoteTestNG.java:251)at org.testng.remote.RemoteTestNG.main(RemoteTestNG.java:77)]]>
            </full-stacktrace>
          </exception> <!-- java.lang.AssertionError -->
          <reporter-output>
          </reporter-output>
        </test-method> <!-- testCos -->
        <test-method status="PASS" signature="resulttime()[pri:0, instance:com.epam.moscow.module4.test.CalculatorTestCos@7c16905e]" name="resulttime" is-config="true" duration-ms="2" started-at="2017-12-16T22:25:45Z" finished-at="2017-12-16T22:25:45Z">
          <reporter-output>
          </reporter-output>
        </test-method> <!-- resulttime -->
      </class> <!-- com.epam.moscow.module4.test.CalculatorTestCos -->
    </test> <!-- Default test -->
  </suite> <!-- Default suite -->
</testng-results>
